<mujoco model="momentum_pendulum">
  <!-- <compiler angle="radian" autolimits="true"/> -->
  <option timestep="0.005"/>
    <size njmax="50" nconmax="10" nstack="200"/>
    <visual>
      <rgba haze=".3 .3 .3 1"/>
      <global offwidth="2560" offheight="1440" elevation="-20" azimuth="120"/>
    </visual>
  <asset>
    <mesh name="base_link" file="base_link.stl" scale="0.001 0.001 0.001"/>
    <mesh name="axis_1_1" file="axis_1_1.stl" scale="0.001 0.001 0.001"/>
    <mesh name="axis_2_1" file="axis_2_1.stl" scale="0.001 0.001 0.001"/>
    <texture type="skybox" builtin="gradient" rgb1="0.6 0.6 0.6" rgb2="0 0 0" width="512" height="512"/>
    <texture name="texplane" type="2d" builtin="checker" rgb1=".25 .25 .25" rgb2=".3 .3 .3" width="512" height="512" mark="cross" markrgb=".8 .8 .8"/>
    <material name="matplane" reflectance="0.3" texture="texplane" texrepeat="1 1" texuniform="true"/>
  </asset>
  <worldbody>
    <geom name="floor" pos="0 0 0" size="0 0 1" type="plane" material="matplane"/>
    <light directional="true" diffuse=".8 .8 .8" specular=".2 .2 .2" pos="0 0 5" dir="0 0 -1"/>
    <body name="rod" pos="0 0 2" euler="90 0 0">
      <geom type="mesh" rgba="0.7 0.7 0.7 1" mesh="base_link"/>
      <joint name="rod_body_joint_X" type="hinge" axis="1 0 0"/>
      <joint name="rod_body_joint_y" type="hinge" axis="0 1 0"/>
        <body name="axis_1_1" pos="0 0.41 0.082" gravcomp="0">
          <inertial pos="0 0 -0.00236136" quat="0.5 0.5 -0.5 0.5" mass="0.253015" diaginertia="0.000683 0.000353 0.000353"/>
          <joint name="axis_1" pos="0 0 0" axis="0 0 1"/>
          <geom pos="0 -0.41 -0.082" type="mesh" rgba="0.7 0.7 0.7 1" mesh="axis_1_1"/>
        </body>
        <body name="axis_2_1" pos="0.082 0.41 0" gravcomp="0">
          <inertial pos="-0.00236136 0 0" mass="0.253015" diaginertia="0.000683 0.000353 0.000353"/>
          <joint name="axis_2" pos="0 0 0" axis="1 0 0"/>
          <geom pos="-0.082 -0.41 0" type="mesh" rgba="0.7 0.7 0.7 1" mesh="axis_2_1"/>
        </body>
    </body>
  </worldbody>
  <actuator>
    <motor gear="1" joint="axis_1"/>
    <motor gear="1" joint="axis_2"/>
  </actuator>
</mujoco>
